Workbook

Sheet Assumptions
A1: DIABLO 400 PoC — BOM-001 Rev 0.3 — Configuration Assumptions
A3: Basis: OCP Diablo 400 Base Specification v0.7.0 (Effective March 1, 2026). Single power rack PoC. All pricing ROM (Rough Order of Magnitude), June 2026, budgetary only — confirm with vendor quotes.
A5: INPUTS (edit blue cells)
A6: Target rack average DC output (kW) | B6: 1000 | C6: Spec §7.3.2 range 800 kW – 1.1 MW (Table 5)
A7: AC/DC PSU rating (kW) | B7: 27 | C7: Table 10, Solution 2 @ 480 VAC
A8: PSUs per 2OU power shelf | B8: 6 | C8: Spec §8.2 "various numbers"; 6 matches Delta 108 kW shelf precedent
A9: Shelf redundancy (+N shelves) | B9: 1 | C9: Designer choice; spec §5 allows redundancy schemes
A10: DC output cable rating (kW) | B10: 100 | C10: Spec §8.1.3 Option 2: 100 kW / 125 A per cable
A11: DC PDU module rating (kW) | B11: 400 | C11: Spec §8.1.3: up to 400 kW per Output Protection & Control Module
A12: AC input voltage (V, 3-phase) | B12: 480 | C12: Table 2, Nominal1
A13: AC tap / cord rating (A) | B13: 200 | C13: Spec §8.1.1: up to 12x 200 A cords
A14: End-to-end efficiency @100% load | B14: 0.97 | C14: Table 9 minimum >97% @ 480 VAC, 50% load; >96.5% @100%
A15: BBU unit power rating (kW) | B15: 80 | C15: Delta GTC 2026 80 kW embedded BBU class (sampling)
A16: Contingency on ROM total | B16: 0.15 | C16: Pre-1.0 spec + sampling hardware = high uncertainty
A17: DERIVED (formulas — do not edit)
A18: Power shelf count (incl. +N) | B18: =ROUNDUP(B6/(B7*B8),0)+B9 -> 8 | C18: Shelves to cover target power, plus redundancy
A19: PSU module count | B19: =B18*B8 -> 48 | C19: Shelves x PSUs per shelf
A20: Installed shelf capacity (kW) | B20: =B19*B7 -> 1296 | C20: Check vs target
A21: DC output cables (qty) | B21: =ROUNDUP(B6/B10,0) -> 10 | C21: 100 kW cables to carry target power
A22: DC PDU modules (qty) | B22: =ROUNDUP(B6/B11,0) -> 3 | C22: 400 kW modules
A23: AC tap kVA each | B23: =B12*B13*SQRT(3)/1000 -> 166.27688 | C23: 480 V x 200 A x sqrt(3)
A24: AC 200 A feeds (qty) | B24: =ROUNDUP(B6/B14/B23,0) -> 7 | C24: DC out / efficiency / tap kVA. Spec max 12 (§8.1.1)
A25: BBU units for 100% load backup (qty) | B25: =ROUNDUP(B6/B15,0) -> 13 | C25: Power-matched per §7.2.1.1 (45–90 s @ 100% load). OPTIONAL

Sheet BOM
A1: Item | B1: Description | C1: Spec Ref | D1: Vendor / Part Family | E1: Status | F1: Qty | G1: Unit | H1: ROM Unit ($) | I1: Ext. ($) | J1: Lead Time | K1: Notes / Alternates
A2: A — RACK MECHANICAL (§6)
A3: A1 | B3: ORV3 rack frame, 48OU, 21-in, ~2329 mm H x 600 mm W x 1200 mm D | C3: §6 | D3: Eaton EORV49RU48B / Rittal ORV3 / Legrand / ATEN RC8000 | E3: Production | F3: 1 | G3: ea | H3: 8000 | I3: =F3*H3 -> 8000 | J3: 8-12 wk | K3: Std ORV3 static rating ~1,600 kg (~3,500 lb) — BELOW 6,000 lb spec target. Reinforced/bespoke frame needed for full compliance.
A4: A2 | B4: Frame reinforcement + custom mods: sliding shelves, blind-mate rails (PSU/BBU/CBU), center-justified busbar mounting | C4: §6.1 | D4: Custom fab (Rittal/Legrand bespoke or local) | E4: Custom Fab | F4: 1 | G4: lot | H4: 15000 | I4: =F4*H4 -> 15000 | J4: 10-14 wk | K4: Blind-mate sliding shelf scheme is non-standard vs 48V ORV3 single-busbar layout.
A5: A3 | B5: Locking safety doors front/rear, partial or full, intrusion switch + emergency shutoff option | C5: §6.1, §11 | D5: Rack vendor option / custom | E5: Custom Fab | F5: 1 | G5: set | H5: 2500 | I5: =F5*H5 -> 2500 | J5: w/ frame | K5: Door pressure drop must be in fan sizing budget (§10.2).
A6: A4 | B6: Side panels / airflow containment, front-to-back | C6: §10.2 | D6: Rack vendor | E6: Production | F6: 1 | G6: set | H6: 1200 | I6: =F6*H6 -> 1200 | J6: w/ frame
A7: A5 | B7: Casters, leveling feet, seismic anchoring kit | C7: §6, §11 | D7: Rack vendor | E7: Production | F7: 1 | G7: set | H7: 800 | I7: =F7*H7 -> 800 | J7: w/ frame | K7: Stability: no tip-over at 10 deg tilt (§11.1).
A8: B — AC INPUT & AC PDU (§7.1, §8.1.1, App D)
A9: B1 | B9: Busway tap-off box, 480 V 3-ph, 200 A, fused | C9: §15.1 | D9: Starline / PDU Cables UL857 tap box | E9: Production | F9: =Assumptions!B24 -> 7 | G9: ea | H9: 3500 | I9: =F9*H9 -> 24500 | J9: 6-10 wk | K9: Tap-box or MTS per App D. Qty derived; spec cap 12x200A.
A10: B2 | B10: 200 A AC whip, 4x1C 3/0 AWG W-type, ~15 m, Molex 1x4 ferrule or lugs | C10: §15.1, Tbl 14 | D10: Custom assembly (PDU Cables etc.) | E10: Custom Fab | F10: =Assumptions!B24 -> 7 | G10: ea | H10: 2200 | I10: =F10*H10 -> 15400 | J10: 4-8 wk | K10: Molex 1x4 connector P/N not verified at catalog level — confirm w/ Molex or use lugs.
A11: B3 | B11: AC PDU panel: up to 12x 200 A inputs, protection fuses, 2-hole lugs or connectorized, output split to shelf feeds (e.g. 200A->4x50A) | C11: §8.1.1 | D11: Custom / ODM build (no catalog item) | E11: Custom Fab | F11: 1 | G11: ea | H11: 18000 | I11: =F11*H11 -> 18000 | J11: 12-16 wk | K11: No purpose-built Diablo AC PDU on market. Assemble from stock fuse blocks + panel, or ODM.
A12: B4 | B12: Quick-connect input option: SurLok Plus 1 kV, 120-200 A class | C12: §6.1, App D | D12: Amphenol SurLok Plus (e.g. SLPPA series) | E12: Production | F12: 16 | G12: ea | H12: 95 | I12: =F12*H12 -> 1520 | J12: stock-4 wk | K12: Spec names "SurLock" — actual family is SurLok/SurLok Plus. UL1977, RADSOK contacts.
A13: B5 | B13: AC PDU-to-power-shelf output cables, 60 A or 100 A, 2 AWG W-type | C13: §8.1.1, §15.1 | D13: Custom assembly | E13: Custom Fab | F13: =Assumptions!B18 -> 8 | G13: ea | H13: 450 | I13: =F13*H13 -> 3600 | J13: 4-6 wk | K13: One feed per shelf assumed; connectors per PSU vendor requirement (§8.2).
A14: C — AC/DC POWER SHELVES & PSUs (§8.2, Tbl 10)
A15: C1 | B15: Power shelf 2OU, 21-24 in, 3-ph AC in, +/-400 VDC out, droop + active current share, bus clip w/ thermal sensor | C15: §8.2 | D15: Delta 108 kW HVDC shelf class / Lite-On / Flex | E15: Sampling | F15: =Assumptions!B18 -> 8 | G15: ea | H15: 4500 | I15: =F15*H15 -> 36000 | J15: eval agmt | K15: CRITICAL LONG-LEAD. Not in distribution — sampling/eval agreement required. ROM estimate only. Load-side target per LVDC WP §3.1: HPR v4 100 kW DC-input shelf (1OU, +39% density vs 72 kW AC HPR v2).
A16: C2 | B16: AC/DC PSU module, 1OU, 27 kW @480 VAC, +/-400 VDC 3-wire galvanically isolated, hot-swap | C16: §8.2.1, Tbl 10 | D16: Delta 18.5 kW (GTC26) / Lite-On / Flex — 27 kW class per Tbl 10 Sol.2 | E16: Sampling | F16: =Assumptions!B19 -> 48 | G16: ea | H16: 3000 | I16: =F16*H16 -> 144000 | J16: eval agmt | K16: Must meet 410->400 V droop (10V +/-0.5V), +/-0.5% reg, 150-180% TDP transient, 1 A/us slew, 20 ms holdup (§7.1.3.1, §7.3). No vendor-verified full compliance yet.
A17: C3 | B17: Shelf control module (Redfish/Modbus PMC) | C17: §8.2.2, §9 | D17: Advanced Energy ORv3 PMC class / vendor PMC | E17: Production | F17: =Assumptions!B18 -> 8 | G17: ea | H17: 600 | I17: =F17*H17 -> 4800 | J17: 4-8 wk | K17: MSFT RSCM / Google module are hyperscaler-internal; use vendor PMC for PoC.
A18: D — +/-400VDC DISTRIBUTION BUSBAR (§8.3)
A19: D1 | B19: Custom vertical 3-conductor busbar (+400 / COM / -400), full rack height, 1.1 MW, air-cooled, touch-safe covers, center-justified | C19: §8.3, §6.1 | D19: Storm Power / Methode / Mersen / Rogers ROLINX (custom) | E19: Custom Fab | F19: 1 | G19: ea | H19: 12000 | I19: =F19*H19 -> 12000 | J19: 10-16 wk | K19: NO catalog 3-conductor +/-400V ORV3 busbar exists. Includes NRE/engineering. Existing ORV3 bars are single-conductor 48 V.
A20: D2 | B20: Busbar HiPot / insulation test + report (>=2x working voltage) | C20: §11.1 | D20: Fab shop or test lab | E20: Service | F20: 1 | G20: lot | H20: 2500 | I20: =F20*H20 -> 2500 | J20: w/ busbar | K20: Stage-gate item before energization.
A21: E — DC PDU / OUTPUT PROTECTION & CONTROL (§8.1.3)
A22: E1 | B22: DC PDU module chassis, 400 kW class: enclosure, busbar attach, output connector panel, integration | C22: §8.1.3 | D22: Custom integration (no catalog item) | E22: Custom Fab | F22: =Assumptions!B22 -> 3 | G22: ea | H22: 8000 | I22: =F22*H22 -> 24000 | J22: 12-16 wk | K22: Assembled from E2-E6 components. Delta SiC e-Fuse shown but not catalog.
A23: E2 | B23: DC fuse, 1000 VDC, 125-160 A class | C23: §8.1.3, §11.1 | D23: Mersen NH gBat / Eaton Bussmann XL-NH | E23: Production | F23: =Assumptions!B21*2+4 -> 24 | G23: ea | H23: 85 | I23: =F23*H23 -> 2040 | J23: stock-6 wk | K23: 2 poles per output cable + spares. IEC 60269-7 battery/PV lines, to 150 kA interrupt. Shelf spec §4.1.1 fixes PDU protection at 2x 80A fuses per 100kW 2-cord shelf — use 80A class per 50kW feed.
A24: E3 | B24: DC contactor/relay, 800-1000 VDC, 150 A class | C24: §8.1.3 | D24: TE Kilovac EV200/ECK / Gigavac GX / Sensata / Panasonic EV | E24: Production | F24: =Assumptions!B21*2 -> 20 | G24: ea | H24: 320 | I24: =F24*H24 -> 6400 | J24: 8-20 wk | K24: EV-grade. Gigavac lead times reportedly long post-Sensata acquisition — order early.
A25: E4 | B25: Ground fault detector / insulation monitor w/ voltage-balance detection (HRG midpoint) | C25: §8.1.4.1.1 | D25: Bender ISOMETER iso685 / isoES425 / iso415R | E25: Production | F25: =Assumptions!B21 -> 10 | G25: ea | H25: 1800 | I25: =F25*H25 -> 18000 | J25: 4-8 wk | K25: Spec requires GFD per output cable for HRG. DESIGN STEER (OCP DCF LVDC WP v1.0 §6.4.1): industry classifies Mt. Diablo as 350/700V Bipolar TN-S w/ distributed M — SOLID midpoint ground, under which GFD is optional per Diablo §8.1.4.2 (~$18K de-scope). Keep >=1 unit for insulation monitoring.
A26: E5 | B26: Per-output ON/OFF switches, LED indicators, signal wiring, relay drivers | C26: §8.1.3 | D26: Stock industrial (panel-mount) | E26: Production | F26: 1 | G26: lot | H26: 1500 | I26: =F26*H26 -> 1500 | J26: stock | K26: Output voltage disconnect before unplug — no live contacts.
A27: E6 | B27: HRG resistor assembly, midpoint-to-PE, concealed/touch-safe | C27: §8.1.4.1 | D27: Stock power resistors / custom mount | E27: Custom Fab | F27: 1 | G27: ea | H27: 400 | I27: =F27*H27 -> 400 | J27: 2-4 wk | K27: Only if HRG selected. LVDC WP steer is TN-S solid midpoint bond (zero-ohm) — replaces resistor w/ fault-current-rated bonding jumper per Diablo §8.1.4.2 (easier fault ID, fuse-based clearing).
A28: E7 | B28: Solid-state circuit breaker (SSCB) / semiconductor-hybrid CB, 800-1000 VDC — ALTERNATE to fuse+contactor per output | C28: §8.1.3 | D28: ABB / Siemens / Eaton / Atom Power (UL 489I / IEC 60947-10) | E28: Optional | F28: 0 | G28: ea | H28: 4500 | I28: =F28*H28 -> 0 | J28: eval agmt | K28: OPTION per LVDC WP §7.2.4.3: us-class clearing, resettable, current-limiting — addresses tens-of-A/us DC fault rise + selectivity. UL 489I new; IEC 60947-10 publishing soon. Qty 0 baseline (fuse+contactor per Diablo spec).
A29: F — DC OUTPUT CABLES & CONNECTORS (§8.4, App C)
A30: F1 | B30: 100 kW / 125 A output cable assy: 4x 1 AWG W-type single conductors, 5 m, 3W+PE+2 sense, NEC 310.60(C)(4) 65C | C30: §8.4, §14.1 | D30: Custom assembly (industrial cable house) | E30: Custom Fab | F30: =Assumptions!B21 -> 10 | G30: ea | H30: 1400 | I30: =F30*H30 -> 14000 | J30: 6-10 wk | K30: 0.1% V-drop budget @ 5 m (§8.4); 15% design margin (App C). INTEROP NOTE: ORV3 HVDC-LVDC 100kW shelf takes 2x 50kW/62.5A cords (not 1x 100kW) — for interop w/ real shelves use Diablo Option 1 (50kW/63A, 4x 4AWG): set Assumptions B10=50, cable qty doubles automatically.
A31: F2 | B31: HV connector set per cable end: +/-400/COM/PE + 2x LMFB sense, 125 A, latching w/ interlock switch | C31: §8.4, Tbl 13 | D31: Amphenol SurLok Plus / HVC2P / Voltarius as bridge; FCI 10183400/01-series when released | E31: Custom Fab | F31: =Assumptions!B21*2 -> 20 | G31: set | H31: 350 | I31: =F31*H31 -> 7000 | J31: 8-12 wk | K31: CORROBORATED: ORV3 HVDC-LVDC 100kW shelf spec v1.0.0 (released 2/20/26) names mating shelf-side receptacle Amphenol 10184015-002LF — same 1018xxxx FCI family as Diablo Tbl 13 P/Ns. Pinout confirmed: P1=-400V, P2=COM, P3=+400V, P4=PE, S1/S2. Cable-side P/Ns (10183400/01) still need Amphenol ICC RFQ — design-lock the family. DC-Crosslink per LVDC WP Fig.35; UL 2278 MCS remains the standards-backed alternate. Note: shelf spec glossary defines LMFB = Low-Side MOSFET Bridge; PSKILL short pin = hot-swap arc mitigation.
A32: F3 | B32: Interlock latch switch integration + de-energize logic (SELV within safety time on unplug) | C32: §8.4 | D32: Custom (w/ E5 relay logic) | E32: Custom Fab | F32: 1 | G32: lot | H32: 2000 | I32: =F32*H32 -> 2000 | J32: w/ E1
A33: G — ENERGY STORAGE (§7.2) — OPTIONAL PER SPEC
A34: G1 | B34: CBU supercapacitor shelf, ~15-20 kW class, UL9540A | C34: §7.2.2 | D34: Eaton XLHV / Delta Power Capacitance Shelf / Lite-On 20 kW | E34: Production | F34: 2 | G34: ea | H34: 7500 | I34: =F34*H34 -> 15000 | J34: 8-12 wk | K34: Strongest available-now option. LVDC WP role: sub-ms shock absorber for AI load steps, coordinated w/ BBU (CBU=immediate transients, BBU=sustained). Not a 45-90 s ride-through substitute.
A35: G2 | B35: BBU 4OU, +/-400 V-class, 80 kW, blind-mate, 45-90 s @ 100% load | C35: §7.2.1 | D35: Delta 80 kW embedded BBU class (GTC 2026) | E35: Optional | F35: =Assumptions!B25 -> 13 | G35: ea | H35: 9000 | I35: =F35*H35 -> 117000 | J35: eval agmt | K35: OPTIONAL config — full 100% load backup power-match. Sampling only; 48 V ORV3 BBUs are production but wrong voltage class. Defer to Stage 2 unless required.
A36: H — MANAGEMENT & TELEMETRY (§9, §10.1)
A37: H1 | B37: Rack management controller, Redfish, Ethernet + CANbus/Modbus internal | C37: §9.1-9.3 | D37: OpenBMC-based / Advanced Energy PMC / Legrand controller | E37: Production | F37: 1 | G37: ea | H37: 1200 | I37: =F37*H37 -> 1200 | J37: 4-6 wk | K37: Redfish recommended by spec; in-rack comm to all building blocks shall be implemented.
A38: H2 | B38: Ethernet switch, protocol gateways (CAN/Modbus), comm harnesses | C38: §9 | D38: Stock industrial | E38: Production | F38: 1 | G38: lot | H38: 1800 | I38: =F38*H38 -> 1800 | J38: stock
A39: H3 | B39: Thermal telemetry: inlet/exhaust air temp, component temps, fan tach/fail, busbar-clip thermistors | C39: §10.1, §8.2 | D39: Vishay NTCALUG54A / TDK B57881S0123F000 / JOYIN JAS103G398FB240001RH | E39: Production | F39: 1 | G39: lot | H39: 600 | I39: =F39*H39 -> 600 | J39: stock | K39: Bus-clip thermistor parts per ORV3 HVDC-LVDC shelf spec §4.9: 150C min, 2K 0.1% pull-up to 3.3V, one per +/- contact — satisfies Diablo §8.2 bus clip thermal sensor.
A40: I — SAFETY & COMPLIANCE (§11)
...

Sheet Summary
A1: DIABLO 400 PoC BOM — Cost Summary (ROM)
A3: Section | B3: Description | C3: Ext. Cost ($)
A4: A | B4: Rack Mechanical (§6) | C4: =SUM(BOM!I3:I7) -> 27500
A5: B | B5: AC Input & AC PDU (§7.1, §8.1.1, App D) | C5: =SUM(BOM!I9:I13) -> 63020
A6: C | B6: AC/DC Power Shelves & PSUs (§8.2) | C6: =SUM(BOM!I15:I17) -> 184800
A7: D | B7: ±400VDC Distribution Busbar (§8.3) | C7: =SUM(BOM!I19:I20) -> 14500
A8: E | B8: DC PDU / Output Protection & Control (§8.1.3) | C8: =SUM(BOM!I22:I28) -> 52340
A9: F | B9: DC Output Cables & Connectors (§8.4, App C) | C9: =SUM(BOM!I30:I32) -> 23000
A10: G | B10: Energy Storage (§7.2) — incl. optional BBU | C10: =SUM(BOM!I34:I35) -> 132000
A11: H | B11: Management & Telemetry (§9) | C11: =SUM(BOM!I37:I39) -> 3600
A12: I | B12: Safety & Compliance (§11) | C12: =SUM(BOM!I41:I44) -> 48000
A13: J | B13: Integration | C13: =SUM(BOM!I46:I47) -> 37500
A14: K | B14: PoC Load / IT-side Validation | C14: =SUM(BOM!I49:I52) -> 30000
B15: Subtotal | C15: =SUM(C4:C14) -> 616260
B16: Contingency | C16: =C15*Assumptions!B16 -> 92439
B17: TOTAL (ROM) | C17: =C15+C16 -> 708699
B19: Total excluding optional BBU (G2) | C19: =C17-SUMIF(BOM!A:A,"G2",BOM!I:I)*(1+Assumptions!B16) -> 574149
